Workbook

Sheet Estimates-on-the-use-of-water-(
A1: name | B1: income_group | C1: pop_n (k) | D1: pop_u% | E1: wat_bas_n | F1: wat_lim_n | G1: wat_unimp_n | H1: wat_sur_n | I1: wat_bas_r | J1: wat_lim_r | K1: wat_unimp_r | L1: wat_sur_r | M1: wat_bas_u | N1: wat_lim_u | O1: wat_unimp_u | P1: wat_sur_u | Q1: pop_n_actual | R1: pop_u_val | S1: pop_r% | T1: pop_n (m) | U1: wat_bas_n (rounded) | V1: pop_u (rounded)% | W1: pop_r (rounded)% | X1: income_group_num
A2: Tokelau | B2: NAN | C2: 1.35 | D2: 0 | E2: 99.707677 | F2: 0 | G2: 0.29232335 | H2: 0 | I2: 99.707677 | J2: 0 | K2: 0.29232335 | L2: 0 | M2: NAN | N2: NAN | O2: NAN | P2: NAN | Q2: =round(C2*1000,0) -> 1350 | R2: =ROUND((D2/100)*Q2,0) -> 0 | S2: =100-D2 -> 100 | T2: =ROUNDUP((C2*1000)/1000000,0) -> 1 | U2: =ROUND(E2,5) -> 99.70768 | V2: =ROUND(D2,0) -> 0 | W2: =ROUND(100-V2,0) -> 100 | X2: =IFS(B2="NAN",0,B2="Low income",1,B2="Lower middle income",2,B2="Upper middle income",3,B2="High income",4) -> 0
A3: Niue | B3: NAN | C3: 1.618 | D3: 46.202003 | E3: 97.010876 | F3: 0 | G3: 2.9891238 | H3: 0 | I3: NAN | J3: NAN | K3: NAN | L3: NAN | M3: NAN | N3: NAN | O3: NAN | P3: NAN | Q3: =round(C3*1000,0) -> 1618 | R3: =ROUND((D3/100)*Q3,0) -> 748 | S3: =100-D3 -> 53.797997 | T3: =ROUNDUP((C3*1000)/1000000,0) -> 1 | U3: =ROUND(E3,5) -> 97.01088 | V3: =ROUND(D3,0) -> 46 | W3: =ROUND(100-V3,0) -> 54 | X3: =IFS(B3="NAN",0,B3="Low income",1,B3="Lower middle income",2,B3="Upper middle income",3,B3="High income",4) -> 0
A4: Falkland Islands (Malvinas) | B4: NAN | C4: 3.483 | D4: 78.507996 | E4: 95.308927 | F4: 0 | G4: 4.6910726 | H4: 0 | I4: 78.172943 | J4: 0 | K4: 21.827057 | L4: 0 | M4: 100 | N4: 0 | O4: 0 | P4: 0 | Q4: =round(C4*1000,0) -> 3483 | R4: =ROUND((D4/100)*Q4,0) -> 2734 | S4: =100-D4 -> 21.492004 | T4: =ROUNDUP((C4*1000)/1000000,0) -> 1 | U4: =ROUND(E4,5) -> 95.30893 | V4: =ROUND(D4,0) -> 79 | W4: =ROUND(100-V4,0) -> 21 | X4: =IFS(B4="NAN",0,B4="Low income",1,B4="Lower middle income",2,B4="Upper middle income",3,B4="High income",4) -> 0
A5: Montserrat | B5: NAN | C5: 4.9990001 | D5: 9.1149998 | E5: 98.077483 | F5: 0 | G5: 1.9225174 | H5: 0 | I5: NAN | J5: NAN | K5: NAN | L5: NAN | M5: NAN | N5: NAN | O5: NAN | P5: NAN | Q5: =round(C5*1000,0) -> 4999 | R5: =ROUND((D5/100)*Q5,0) -> 456 | S5: =100-D5 -> 90.885 | T5: =ROUNDUP((C5*1000)/1000000,0) -> 1 | U5: =ROUND(E5,5) -> 98.07748 | V5: =ROUND(D5,0) -> 9 | W5: =ROUND(100-V5,0) -> 91 | X5: =IFS(B5="NAN",0,B5="Low income",1,B5="Lower middle income",2,B5="Upper middle income",3,B5="High income",4) -> 0
A6: Saint Pierre and Miquelon | B6: NAN | C6: 5.7950001 | D6: 89.961998 | E6: 91.4 | F6: 0 | G6: 8.6 | H6: 0 | I6: NAN | J6: NAN | K6: NAN | L6: NAN | M6: NAN | N6: NAN | O6: NAN | P6: NAN | Q6: =round(C6*1000,0) -> 5795 | R6: =ROUND((D6/100)*Q6,0) -> 5213 | S6: =100-D6 -> 10.038002 | T6: =ROUNDUP((C6*1000)/1000000,0) -> 1 | U6: =ROUND(E6,5) -> 91.4 | V6: =ROUND(D6,0) -> 90 | W6: =ROUND(100-V6,0) -> 10 | X6: =IFS(B6="NAN",0,B6="Low income",1,B6="Lower middle income",2,B6="Upper middle income",3,B6="High income",4) -> 0
A7: Saint Helena | B7: NAN | C7: 6.0710001 | D7: 40.082001 | E7: 99.1 | F7: 0 | G7: 0.9 | H7: 0 | I7: NAN | J7: NAN | K7: NAN | L7: NAN | M7: NAN | N7: NAN | O7: NAN | P7: NAN | Q7: =round(C7*1000,0) -> 6071 | R7: =ROUND((D7/100)*Q7,0) -> 2433 | S7: =100-D7 -> 59.917999 | T7: =ROUNDUP((C7*1000)/1000000,0) -> 1 | U7: =ROUND(E7,5) -> 99.1 | V7: =ROUND(D7,0) -> 40 | W7: =ROUND(100-V7,0) -> 60 | X7: =IFS(B7="NAN",0,B7="Low income",1,B7="Lower middle income",2,B7="Upper middle income",3,B7="High income",4) -> 0
A8: Saint Barthelemy | B8: NAN | C8: 9.885 | D8: 100 | E8: 100 | F8: 0 | G8: 0 | H8: 0 | I8: NAN | J8: NAN | K8: NAN | L8: NAN | M8: 100 | N8: 0 | O8: 0 | P8: 0 | Q8: =round(C8*1000,0) -> 9885 | R8: =ROUND((D8/100)*Q8,0) -> 9885 | S8: =100-D8 -> 0 | T8: =ROUNDUP((C8*1000)/1000000,0) -> 1 | U8: =ROUND(E8,5) -> 100 | V8: =ROUND(D8,0) -> 100 | W8: =ROUND(100-V8,0) -> 0 | X8: =IFS(B8="NAN",0,B8="Low income",1,B8="Lower middle income",2,B8="Upper middle income",3,B8="High income",4) -> 0
A9: Nauru | B9: High income | C9: 10.834 | D9: 100 | E9: 100 | F9: 0 | G9: 0 | H9: 0 | I9: NAN | J9: NAN | K9: NAN | L9: NAN | M9: 100 | N9: 0 | O9: 0 | P9: 0 | Q9: =round(C9*1000,0) -> 10834 | R9: =ROUND((D9/100)*Q9,0) -> 10834 | S9: =100-D9 -> 0 | T9: =ROUNDUP((C9*1000)/1000000,0) -> 1 | U9: =ROUND(E9,5) -> 100 | V9: =ROUND(D9,0) -> 100 | W9: =ROUND(100-V9,0) -> 0 | X9: =IFS(B9="NAN",0,B9="Low income",1,B9="Lower middle income",2,B9="Upper middle income",3,B9="High income",4) -> 4
A10: Wallis and Futuna Islands | B10: NAN | C10: 11.246 | D10: 0 | E10: 99.143287 | F10: 0 | G10: 0.85671264 | H10: 0 | I10: 99.143287 | J10: 0 | K10: 0.85671264 | L10: 0 | M10: NAN | N10: NAN | O10: NAN | P10: NAN | Q10: =round(C10*1000,0) -> 11246 | R10: =ROUND((D10/100)*Q10,0) -> 0 | S10: =100-D10 -> 100 | T10: =ROUNDUP((C10*1000)/1000000,0) -> 1 | U10: =ROUND(E10,5) -> 99.14329 | V10: =ROUND(D10,0) -> 0 | W10: =ROUND(100-V10,0) -> 100 | X10: =IFS(B10="NAN",0,B10="Low income",1,B10="Lower middle income",2,B10="Upper middle income",3,B10="High income",4) -> 0
A11: Tuvalu | B11: Upper middle income | C11: 11.792 | D11: 64.014 | E11: 100 | F11: 0 | G11: 0 | H11: 0 | I11: 100 | J11: 0 | K11: 0 | L11: 0 | M11: 100 | N11: 0 | O11: 0 | P11: 0 | Q11: =round(C11*1000,0) -> 11792 | R11: =ROUND((D11/100)*Q11,0) -> 7549 | S11: =100-D11 -> 35.986 | T11: =ROUNDUP((C11*1000)/1000000,0) -> 1 | U11: =ROUND(E11,5) -> 100 | V11: =ROUND(D11,0) -> 64 | W11: =ROUND(100-V11,0) -> 36 | X11: =IFS(B11="NAN",0,B11="Low income",1,B11="Lower middle income",2,B11="Upper middle income",3,B11="High income",4) -> 3
A12: Cook Islands | B12: NAN | C12: 17.563999 | D12: 75.495003 | E12: 99.97161 | F12: 0 | G12: 0.028389783 | H12: 0 | I12: NAN | J12: NAN | K12: NAN | L12: NAN | M12: NAN | N12: NAN | O12: NAN | P12: NAN | Q12: =round(C12*1000,0) -> 17564 | R12: =ROUND((D12/100)*Q12,0) -> 13260 | S12: =100-D12 -> 24.504997 | T12: =ROUNDUP((C12*1000)/1000000,0) -> 1 | U12: =ROUND(E12,5) -> 99.97161 | V12: =ROUND(D12,0) -> 75 | W12: =ROUND(100-V12,0) -> 25 | X12: =IFS(B12="NAN",0,B12="Low income",1,B12="Lower middle income",2,B12="Upper middle income",3,B12="High income",4) -> 0
A13: Palau | B13: Upper middle income | C13: 18.091999 | D13: 80.987999 | E13: 99.657545 | F13: 0 | G13: 0.3424545 | H13: 0 | I13: 99.756985 | J13: 0 | K13: 0.24301497 | L13: 0 | M13: 99.634202 | N13: 0 | O13: 0.36579801 | P13: 0 | Q13: =round(C13*1000,0) -> 18092 | R13: =ROUND((D13/100)*Q13,0) -> 14652 | S13: =100-D13 -> 19.012001 | T13: =ROUNDUP((C13*1000)/1000000,0) -> 1 | U13: =ROUND(E13,5) -> 99.65755 | V13: =ROUND(D13,0) -> 81 | W13: =ROUND(100-V13,0) -> 19 | X13: =IFS(B13="NAN",0,B13="Low income",1,B13="Lower middle income",2,B13="Upper middle income",3,B13="High income",4) -> 3
A14: British Virgin Islands | B14: High income | C14: 30.237 | D14: 48.514999 | E14: 99.864384 | F14: 0 | G14: 0.13561644 | H14: 0 | I14: NAN | J14: NAN | K14: NAN | L14: NAN | M14: NAN | N14: NAN | O14: NAN | P14: NAN | Q14: =round(C14*1000,0) -> 30237 | R14: =ROUND((D14/100)*Q14,0) -> 14669 | S14: =100-D14 -> 51.485001 | T14: =ROUNDUP((C14*1000)/1000000,0) -> 1 | U14: =ROUND(E14,5) -> 99.86438 | V14: =ROUND(D14,0) -> 49 | W14: =ROUND(100-V14,0) -> 51 | X14: =IFS(B14="NAN",0,B14="Low income",1,B14="Lower middle income",2,B14="Upper middle income",3,B14="High income",4) -> 4
A15: Gibraltar | B15: High income | C15: 33.691002 | D15: 100 | E15: 100 | F15: 0 | G15: 0 | H15: 0 | I15: NAN | J15: NAN | K15: NAN | L15: NAN | M15: 100 | N15: 0 | O15: 0 | P15: 0 | Q15: =round(C15*1000,0) -> 33691 | R15: =ROUND((D15/100)*Q15,0) -> 33691 | S15: =100-D15 -> 0 | T15: =ROUNDUP((C15*1000)/1000000,0) -> 1 | U15: =ROUND(E15,5) -> 100 | V15: =ROUND(D15,0) -> 100 | W15: =ROUND(100-V15,0) -> 0 | X15: =IFS(B15="NAN",0,B15="Low income",1,B15="Lower middle income",2,B15="Upper middle income",3,B15="High income",4) -> 4
A16: San Marino | B16: High income | C16: 33.938 | D16: 97.499001 | E16: 100 | F16: 0 | G16: 0 | H16: 0 | I16: NAN | J16: NAN | K16: NAN | L16: NAN | M16: NAN | N16: NAN | O16: NAN | P16: NAN | Q16: =round(C16*1000,0) -> 33938 | R16: =ROUND((D16/100)*Q16,0) -> 33089 | S16: =100-D16 -> 2.5009995 | T16: =ROUNDUP((C16*1000)/1000000,0) -> 1 | U16: =ROUND(E16,5) -> 100 | V16: =ROUND(D16,0) -> 97 | W16: =ROUND(100-V16,0) -> 3 | X16: =IFS(B16="NAN",0,B16="Low income",1,B16="Lower middle income",2,B16="Upper middle income",3,B16="High income",4) -> 4
A17: Liechtenstein | B17: High income | C17: 38.137001 | D17: 14.416 | E17: 100 | F17: 0 | G17: 0 | H17: 0 | I17: NAN | J17: NAN | K17: NAN | L17: NAN | M17: NAN | N17: NAN | O17: NAN | P17: NAN | Q17: =round(C17*1000,0) -> 38137 | R17: =ROUND((D17/100)*Q17,0) -> 5498 | S17: =100-D17 -> 85.584 | T17: =ROUNDUP((C17*1000)/1000000,0) -> 1 | U17: =ROUND(E17,5) -> 100 | V17: =ROUND(D17,0) -> 14 | W17: =ROUND(100-V17,0) -> 86 | X17: =IFS(B17="NAN",0,B17="Low income",1,B17="Lower middle income",2,B17="Upper middle income",3,B17="High income",4) -> 4
A18: Saint Martin (French part) | B18: High income | C18: 38.659 | D18: 100 | E18: 99.999271 | F18: 0 | G18: 0.00072861055 | H18: 0 | I18: NAN | J18: NAN | K18: NAN | L18: NAN | M18: 99.999271 | N18: 0 | O18: 0.00072861055 | P18: 0 | Q18: =round(C18*1000,0) -> 38659 | R18: =ROUND((D18/100)*Q18,0) -> 38659 | S18: =100-D18 -> 0 | T18: =ROUNDUP((C18*1000)/1000000,0) -> 1 | U18: =ROUND(E18,5) -> 99.99927 | V18: =ROUND(D18,0) -> 100 | W18: =ROUND(100-V18,0) -> 0 | X18: =IFS(B18="NAN",0,B18="Low income",1,B18="Lower middle income",2,B18="Upper middle income",3,B18="High income",4) -> 4
A19: Monaco | B19: High income | C19: 39.243999 | D19: 100 | E19: 100 | F19: 0 | G19: 0 | H19: 0 | I19: NAN | J19: NAN | K19: NAN | L19: NAN | M19: 100 | N19: 0 | O19: 0 | P19: 0 | Q19: =round(C19*1000,0) -> 39244 | R19: =ROUND((D19/100)*Q19,0) -> 39244 | S19: =100-D19 -> 0 | T19: =ROUNDUP((C19*1000)/1000000,0) -> 1 | U19: =ROUND(E19,5) -> 100 | V19: =ROUND(D19,0) -> 100 | W19: =ROUND(100-V19,0) -> 0 | X19: =IFS(B19="NAN",0,B19="Low income",1,B19="Lower middle income",2,B19="Upper middle income",3,B19="High income",4) -> 4
A20: Faeroe Islands | B20: High income | C20: 48.865002 | D20: 42.397999 | E20: 100 | F20: 0 | G20: 0 | H20: 0 | I20: NAN | J20: NAN | K20: NAN | L20: NAN | M20: NAN | N20: NAN | O20: NAN | P20: NAN | Q20: =round(C20*1000,0) -> 48865 | R20: =ROUND((D20/100)*Q20,0) -> 20718 | S20: =100-D20 -> 57.602001 | T20: =ROUNDUP((C20*1000)/1000000,0) -> 1 | U20: =ROUND(E20,5) -> 100 | V20: =ROUND(D20,0) -> 42 | W20: =ROUND(100-V20,0) -> 58 | X20: =IFS(B20="NAN",0,B20="Low income",1,B20="Lower middle income",2,B20="Upper middle income",3,B20="High income",4) -> 4
A21: American Samoa | B21: Upper middle income | C21: 55.196999 | D21: 87.153 | E21: 99.773772 | F21: 0 | G21: 0.22622834 | H21: 0 | I21: NAN | J21: NAN | K21: NAN | L21: NAN | M21: NAN | N21: NAN | O21: NAN | P21: NAN | Q21: =round(C21*1000,0) -> 55197 | R21: =ROUND((D21/100)*Q21,0) -> 48106 | S21: =100-D21 -> 12.847 | T21: =ROUNDUP((C21*1000)/1000000,0) -> 1 | U21: =ROUND(E21,5) -> 99.77377 | V21: =ROUND(D21,0) -> 87 | W21: =ROUND(100-V21,0) -> 13 | X21: =IFS(B21="NAN",0,B21="Low income",1,B21="Lower middle income",2,B21="Upper middle income",3,B21="High income",4) -> 3
A22: Greenland | B22: High income | C22: 56.771999 | D22: 87.282005 | E22: 100 | F22: 0 | G22: 0 | H22: 0 | I22: 100 | J22: 0 | K22: 0 | L22: 0 | M22: 100 | N22: 0 | O22: 0 | P22: 0 | Q22: =round(C22*1000,0) -> 56772 | R22: =ROUND((D22/100)*Q22,0) -> 49552 | S22: =100-D22 -> 12.717995 | T22: =ROUNDUP((C22*1000)/1000000,0) -> 1 | U22: =ROUND(E22,5) -> 100 | V22: =ROUND(D22,0) -> 87 | W22: =ROUND(100-V22,0) -> 13 | X22: =IFS(B22="NAN",0,B22="Low income",1,B22="Lower middle income",2,B22="Upper middle income",3,B22="High income",4) -> 4
A23: Northern Mariana Islands | B23: High income | C23: 57.556999 | D23: 91.797997 | E23: 100 | F23: 0 | G23: 0 | H23: 0 | I23: NAN | J23: NAN | K23: NAN | L23: NAN | M23: NAN | N23: NAN | O23: NAN | P23: NAN | Q23: =round(C23*1000,0) -> 57557 | R23: =ROUND((D23/100)*Q23,0) -> 52836 | S23: =100-D23 -> 8.2020035 | T23: =ROUNDUP((C23*1000)/1000000,0) -> 1 | U23: =ROUND(E23,5) -> 100 | V23: =ROUND(D23,0) -> 92 | W23: =ROUND(100-V23,0) -> 8 | X23: =IFS(B23="NAN",0,B23="Low income",1,B23="Lower middle income",2,B23="Upper middle income",3,B23="High income",4) -> 4
A24: Marshall Islands | B24: Upper middle income | C24: 59.194 | D24: 77.793991 | E24: 88.572047 | F24: 11.387979 | G24: 0.039974026 | H24: 0 | I24: 94.42972 | J24: 5.39028 | K24: 0.18 | L24: 0 | M24: 86.9 | N24: 13.1 | O24: 0 | P24: 0 | Q24: =round(C24*1000,0) -> 59194 | R24: =ROUND((D24/100)*Q24,0) -> 46049 | S24: =100-D24 -> 22.206009 | T24: =ROUNDUP((C24*1000)/1000000,0) -> 1 | U24: =ROUND(E24,5) -> 88.57205 | V24: =ROUND(D24,0) -> 78 | W24: =ROUND(100-V24,0) -> 22 | X24: =IFS(B24="NAN",0,B24="Low income",1,B24="Lower middle income",2,B24="Upper middle income",3,B24="High income",4) -> 3
A25: Bermuda | B25: High income | C25: 62.272999 | D25: 100 | E25: 99.90314 | F25: 0 | G25: 0.096859983 | H25: 0 | I25: NAN | J25: NAN | K25: NAN | L25: NAN | M25: 99.90314 | N25: 0 | O25: 0.096859983 | P25: 0 | Q25: =round(C25*1000,0) -> 62273 | R25: =ROUND((D25/100)*Q25,0) -> 62273 | S25: =100-D25 -> 0 | T25: =ROUNDUP((C25*1000)/1000000,0) -> 1 | U25: =ROUND(E25,5) -> 99.90314 | V25: =ROUND(D25,0) -> 100 | W25: =ROUND(100-V25,0) -> 0 | X25: =IFS(B25="NAN",0,B25="Low income",1,B25="Lower middle income",2,B25="Upper middle income",3,B25="High income",4) -> 4
A26: Andorra | B26: High income | C26: 77.264999 | D26: 87.916 | E26: 100 | F26: 0 | G26: 0 | H26: 0 | I26: 100 | J26: 0 | K26: 0 | L26: 0 | M26: 100 | N26: 0 | O26: 0 | P26: 0 | Q26: =round(C26*1000,0) -> 77265 | R26: =ROUND((D26/100)*Q26,0) -> 67928 | S26: =100-D26 -> 12.084 | T26: =ROUNDUP((C26*1000)/1000000,0) -> 1 | U26: =ROUND(E26,5) -> 100 | V26: =ROUND(D26,0) -> 88 | W26: =ROUND(100-V26,0) -> 12 | X26: =IFS(B26="NAN",0,B26="Low income",1,B26="Lower middle income",2,B26="Upper middle income",3,B26="High income",4) -> 4
A27: Isle of Man | B27: High income | C27: 85.031998 | D27: 52.898003 | E27: 99.075 | F27: 0 | G27: 0.925 | H27: 0 | I27: NAN | J27: NAN | K27: NAN | L27: NAN | M27: NAN | N27: NAN | O27: NAN | P27: NAN | Q27: =round(C27*1000,0) -> 85032 | R27: =ROUND((D27/100)*Q27,0) -> 44980 | S27: =100-D27 -> 47.101997 | T27: =ROUNDUP((C27*1000)/1000000,0) -> 1 | U27: =ROUND(E27,5) -> 99.075 | V27: =ROUND(D27,0) -> 53 | W27: =ROUND(100-V27,0) -> 47 | X27: =IFS(B27="NAN",0,B27="Low income",1,B27="Lower middle income",2,B27="Upper middle income",3,B27="High income",4) -> 4
A28: United States Virgin Islands | B28: High income | C28: 104.423 | D28: 95.939003 | E28: 98.718267 | F28: 0 | G28: 1.2817326 | H28: 0 | I28: NAN | J28: NAN | K28: NAN | L28: NAN | M28: NAN | N28: NAN | O28: NAN | P28: NAN | Q28: =round(C28*1000,0) -> 104423 | R28: =ROUND((D28/100)*Q28,0) -> 100182 | S28: =100-D28 -> 4.060997 | T28: =ROUNDUP((C28*1000)/1000000,0) -> 1 | U28: =ROUND(E28,5) -> 98.71827 | V28: =ROUND(D28,0) -> 96 | W28: =ROUND(100-V28,0) -> 4 | X28: =IFS(B28="NAN",0,B28="Low income",1,B28="Lower middle income",2,B28="Upper middle income",3,B28="High income",4) -> 4
A29: Tonga | B29: Upper middle income | C29: 105.697 | D29: 23.098999 | E29: 98.731081 | F29: 0.8814973 | G29: 0.38742188 | H29: 0 | I29: 98.468079 | J29: 1.1031597 | K29: 0.42876176 | L29: 0 | M29: 99.606658 | N29: 0.14354054 | O29: 0.24980128 | P29: 0 | Q29: =round(C29*1000,0) -> 105697 | R29: =ROUND((D29/100)*Q29,0) -> 24415 | S29: =100-D29 -> 76.901001 | T29: =ROUNDUP((C29*1000)/1000000,0) -> 1 | U29: =ROUND(E29,5) -> 98.73108 | V29: =ROUND(D29,0) -> 23 | W29: =ROUND(100-V29,0) -> 77 | X29: =IFS(B29="NAN",0,B29="Low income",1,B29="Lower middle income",2,B29="Upper middle income",3,B29="High income",4) -> 3
A30: Kiribati | B30: Lower middle income | C30: 119.446 | D30: 55.593998 | E30: 77.970921 | F30: 4.0768996 | G30: 17.95218 | H30: 0 | I30: 60.994185 | J30: 2.0966098 | K30: 36.909205 | L30: 0 | M30: 91.531175 | N30: 5.6586665 | O30: 2.8101587 | P30: 0 | Q30: =round(C30*1000,0) -> 119446 | R30: =ROUND((D30/100)*Q30,0) -> 66405 | S30: =100-D30 -> 44.406002 | T30: =ROUNDUP((C30*1000)/1000000,0) -> 1 | U30: =ROUND(E30,5) -> 77.97092 | V30: =ROUND(D30,0) -> 56 | W30: =ROUND(100-V30,0) -> 44 | X30: =IFS(B30="NAN",0,B30="Low income",1,B30="Lower middle income",2,B30="Upper middle income",3,B30="High income",4) -> 2
A31: Guam | B31: High income | C31: 168.783 | D31: 94.938004 | E31: 99.6952 | F31: 0 | G31: 0.3048 | H31: 0 | I31: NAN | J31: NAN | K31: NAN | L31: NAN | M31: NAN | N31: NAN | O31: NAN | P31: NAN | Q31: =round(C31*1000,0) -> 168783 | R31: =ROUND((D31/100)*Q31,0) -> 160239 | S31: =100-D31 -> 5.0619965 | T31: =ROUNDUP((C31*1000)/1000000,0) -> 1 | U31: =ROUND(E31,5) -> 99.6952 | V31: =ROUND(D31,0) -> 95 | W31: =ROUND(100-V31,0) -> 5 | X31: =IFS(B31="NAN",0,B31="Low income",1,B31="Lower middle income",2,B31="Upper middle income",3,B31="High income",4) -> 4
A32: Saint Lucia | B32: Upper middle income | C32: 183.629 | D32: 18.841 | E32: 96.887845 | F32: 1.8156522 | G32: 1.2965033 | H32: 0 | I32: 96.814024 | J32: 1.7341523 | K32: 1.4518239 | L32: 0 | M32: 97.205822 | N32: 2.1667189 | O32: 0.62745892 | P32: 0 | Q32: =round(C32*1000,0) -> 183629 | R32: =ROUND((D32/100)*Q32,0) -> 34598 | S32: =100-D32 -> 81.159 | T32: =ROUNDUP((C32*1000)/1000000,0) -> 1 | U32: =ROUND(E32,5) -> 96.88784 | V32: =ROUND(D32,0) -> 19 | W32: =ROUND(100-V32,0) -> 81 | X32: =IFS(B32="NAN",0,B32="Low income",1,B32="Lower middle income",2,B32="Upper middle income",3,B32="High income",4) -> 3
A33: Samoa | B33: Lower middle income | C33: 198.41 | D33: 17.889 | E33: 91.837725 | F33: 6.5209 | G33: 1.4186234 | H33: 0.22275207 | I33: 91.780323 | J33: 6.2207033 | K33: 1.7276922 | L33: 0.27128163 | M33: 92.10119 | N33: 7.89881 | O33: 0 | P33: 0 | Q33: =round(C33*1000,0) -> 198410 | R33: =ROUND((D33/100)*Q33,0) -> 35494 | S33: =100-D33 -> 82.111 | T33: =ROUNDUP((C33*1000)/1000000,0) -> 1 | U33: =ROUND(E33,5) -> 91.83772 | V33: =ROUND(D33,0) -> 18 | W33: =ROUND(100-V33,0) -> 82 | X33: =IFS(B33="NAN",0,B33="Low income",1,B33="Lower middle income",2,B33="Upper middle income",3,B33="High income",4) -> 2
A34: Sao Tome and Principe | B34: Lower middle income | C34: 219.161 | D34: 74.354004 | E34: 78.226455 | F34: 20.237983 | G34: 0.44351993 | H34: 1.0920419 | I34: 74.300614 | J34: 19.711843 | K34: 1.7294057 | L34: 4.2581372 | M34: 79.580543 | N34: 20.419457 | O34: 0 | P34: 0 | Q34: =round(C34*1000,0) -> 219161 | R34: =ROUND((D34/100)*Q34,0) -> 162955 | S34: =100-D34 -> 25.645996 | T34: =ROUNDUP((C34*1000)/1000000,0) -> 1 | U34: =ROUND(E34,5) -> 78.22646 | V34: =ROUND(D34,0) -> 74 | W34: =ROUND(100-V34,0) -> 26 | X34: =IFS(B34="NAN",0,B34="Low income",1,B34="Lower middle income",2,B34="Upper middle income",3,B34="High income",4) -> 2
A35: Mayotte | B35: NAN | C35: 272.81299 | D35: 45.750999 | E35: 96.37118 | F35: 0 | G35: 3.6288203 | H35: NAN | I35: NAN | J35: NAN | K35: NAN | L35: NAN | M35: NAN | N35: NAN | O35: NAN | P35: NAN | Q35: =round(C35*1000,0) -> 272813 | R35: =ROUND((D35/100)*Q35,0) -> 124815 | S35: =100-D35 -> 54.249001 | T35: =ROUNDUP((C35*1000)/1000000,0) -> 1 | U35: =ROUND(E35,5) -> 96.37118 | V35: =ROUND(D35,0) -> 46 | W35: =ROUND(100-V35,0) -> 54 | X35: =IFS(B35="NAN",0,B35="Low income",1,B35="Lower middle income",2,B35="Upper middle income",3,B35="High income",4) -> 0
A36: French Polynesia | B36: High income | C36: 280.90399 | D36: 61.975002 | E36: 100 | F36: 0 | G36: 0 | H36: 0 | I36: NAN | J36: NAN | K36: NAN | L36: NAN | M36: NAN | N36: NAN | O36: NAN | P36: NAN | Q36: =round(C36*1000,0) -> 280904 | R36: =ROUND((D36/100)*Q36,0) -> 174090 | S36: =100-D36 -> 38.024998 | T36: =ROUNDUP((C36*1000)/1000000,0) -> 1 | U36: =ROUND(E36,5) -> 100 | V36: =ROUND(D36,0) -> 62 | W36: =ROUND(100-V36,0) -> 38 | X36: =IFS(B36="NAN",0,B36="Low income",1,B36="Lower middle income",2,B36="Upper middle income",3,B36="High income",4) -> 4
A37: New Caledonia | B37: High income | C37: 285.491 | D37: 71.517998 | E37: 99.305321 | F37: 0 | G37: 0.69467943 | H37: 0 | I37: NAN | J37: NAN | K37: NAN | L37: NAN | M37: NAN | N37: NAN | O37: NAN | P37: NAN | Q37: =round(C37*1000,0) -> 285491 | R37: =ROUND((D37/100)*Q37,0) -> 204177 | S37: =100-D37 -> 28.482002 | T37: =ROUNDUP((C37*1000)/1000000,0) -> 1 | U37: =ROUND(E37,5) -> 99.30532 | V37: =ROUND(D37,0) -> 72 | W37: =ROUND(100-V37,0) -> 28 | X37: =IFS(B37="NAN",0,B37="Low income",1,B37="Lower middle income",2,B37="Upper middle income",3,B37="High income",4) -> 4
A38: Barbados | B38: High income | C38: 287.371 | D38: 31.191 | E38: 98.51445 | F38: 0.26760058 | G38: 1.217949 | H38: 0 | I38: NAN | J38: NAN | K38: NAN | L38: NAN | M38: NAN | N38: NAN | O38: NAN | P38: NAN | Q38: =round(C38*1000,0) -> 287371 | R38: =ROUND((D38/100)*Q38,0) -> 89634 | S38: =100-D38 -> 68.809 | T38: =ROUNDUP((C38*1000)/1000000,0) -> 1 | U38: =ROUND(E38,5) -> 98.51445 | V38: =ROUND(D38,0) -> 31 | W38: =ROUND(100-V38,0) -> 69 | X38: =IFS(B38="NAN",0,B38="Low income",1,B38="Lower middle income",2,B38="Upper middle income",3,B38="High income",4) -> 4
A39: French Guiana | B39: NAN | C39: 298.68201 | D39: 85.82 | E39: 93.782216 | F39: 0 | G39: 6.2177837 | H39: 0 | I39: NAN | J39: NAN | K39: NAN | L39: NAN | M39: NAN | N39: NAN | O39: NAN | P39: NAN | Q39: =round(C39*1000,0) -> 298682 | R39: =ROUND((D39/100)*Q39,0) -> 256329 | S39: =100-D39 -> 14.18 | T39: =ROUNDUP((C39*1000)/1000000,0) -> 1 | U39: =ROUND(E39,5) -> 93.78222 | V39: =ROUND(D39,0) -> 86 | W39: =ROUND(100-V39,0) -> 14 | X39: =IFS(B39="NAN",0,B39="Low income",1,B39="Lower middle income",2,B39="Upper middle income",3,B39="High income",4) -> 0
A40: Vanuatu | B40: Lower middle income | C40: 307.14999 | D40: 25.525002 | E40: 91.231191 | F40: 1.0623851 | G40: 0 | H40: 7.7064242 | I40: 88.397201 | J40: 1.2551327 | K40: 0 | L40: 10.347666 | M40: 99.5 | N40: 0.5 | O40: 0 | P40: 0 | Q40: =round(C40*1000,0) -> 307150 | R40: =ROUND((D40/100)*Q40,0) -> 78400 | S40: =100-D40 -> 74.474998 | T40: =ROUNDUP((C40*1000)/1000000,0) -> 1 | U40: =ROUND(E40,5) -> 91.23119 | V40: =ROUND(D40,0) -> 26 | W40: =ROUND(100-V40,0) -> 74 | X40: =IFS(B40="NAN",0,B40="Low income",1,B40="Lower middle income",2,B40="Upper middle income",3,B40="High income",4) -> 2
...

Sheet Pivot Table 5

Sheet Income group pivot Table 
A11: 0 → NaN
A12: 1 → Low income
A13: 2 → Lower middle income
A14: 3 → Upper middle income
A15: 4 → High income

Sheet Rural pivot Table 

Sheet Urban pivot Table 

Sheet National pivot Table 

Sheet Global 2020 Report
A1: total_pop_n_actual | C1: estimated_pop_n | E1: total_pop_u_val | G1: estimated_pop_u_val | I1: pop_u% | K1: estimated_pop_u%
A2: =SUM('Estimates-on-the-use-of-water-('!Q2:Q214) -> 7786695108 | C2: =7.821*1000000000 -> 7821000000 | E2: =SUM('Estimates-on-the-use-of-water-('!R2:R214) -> 4375308457 | G2: =(55/100)*C2 -> 4301550000 | I2: =E2/A2*100 -> 56.189544 | K2: 55
B5: percentage_difference_pop_n | F5: percentage_difference_pop_u | J5: percentage_difference_pop_u%
B6: =((ABS(A2-C2))/(SUM(A2,C2)/2))*100 -> 0.43958947 | F6: =((ABS(E2-G2))/(SUM(E2,G2)/2))*100 -> 1.7001189 | J6: =((ABS(I2-K2))/(SUM(I2,K2)/2))*100 -> 2.1396684
G11: AVERAGE
B12: min | C12: q1 | D12: median q2 | E12: q3 | F12: max | G12: mean | H12: mode | I12: range | J12: (IQR)interquartile range | K12: standard deviation
A13: wat_bas_n_rounded | B13: =MIN('Estimates-on-the-use-of-water-('!U2:U214) -> 37.2024 | C13: =QUARTILE('Estimates-on-the-use-of-water-('!U2:U214,1) -> 85.643315 | D13: =MEDIAN('Estimates-on-the-use-of-water-('!U2:U214) -> 97.34814 | E13: =QUARTILE('Estimates-on-the-use-of-water-('!U2:U214,3) -> 99.887525 | F13: =MAX('Estimates-on-the-use-of-water-('!U2:U214) -> 100 | G13: =AVERAGE('Estimates-on-the-use-of-water-('!U2:U214) -> 89.864783 | H13: =MODE('Estimates-on-the-use-of-water-('!U2:U214) -> 100 | I13: =F13-B13 -> 62.7976 | J13: =E13-C13 -> 14.24421 | K13: =STDEV('Estimates-on-the-use-of-water-('!U2:U214) -> 15.087427
A14: wat_lim_n | B14: =MIN('Estimates-on-the-use-of-water-('!F2:F214) -> 0 | C14: =QUARTILE('Estimates-on-the-use-of-water-('!F2:F214,1) -> 0 | D14: =MEDIAN('Estimates-on-the-use-of-water-('!F2:F214) -> 0.47078292 | E14: =QUARTILE('Estimates-on-the-use-of-water-('!F2:F214,3) -> 4.8512192 | F14: =MAX('Estimates-on-the-use-of-water-('!F2:F214) -> 37.426963 | G14: =AVERAGE('Estimates-on-the-use-of-water-('!F2:F214) -> 3.8652653 | H14: =MODE('Estimates-on-the-use-of-water-('!F2:F214) -> 0 | I14: =F14-B14 -> 37.426963 | J14: =E14-C14 -> 4.8512192 | K14: =STDEV('Estimates-on-the-use-of-water-('!F2:F214) -> 6.9608466
A15: wat_unimp_n | B15: =MIN('Estimates-on-the-use-of-water-('!G2:G214) -> 0 | C15: =QUARTILE('Estimates-on-the-use-of-water-('!G2:G214,1) -> 0.033906223 | D15: =MEDIAN('Estimates-on-the-use-of-water-('!G2:G214) -> 0.85364747 | E15: =QUARTILE('Estimates-on-the-use-of-water-('!G2:G214,3) -> 5.2793099 | F15: =MAX('Estimates-on-the-use-of-water-('!G2:G214) -> 33.539114 | G15: =AVERAGE('Estimates-on-the-use-of-water-('!G2:G214) -> 4.4180107 | H15: =MODE('Estimates-on-the-use-of-water-('!G2:G214) -> 0 | I15: =F15-B15 -> 33.539114 | J15: =E15-C15 -> 5.2454037 | K15: =STDEV('Estimates-on-the-use-of-water-('!G2:G214) -> 7.174477
A16: wat_sur_n | B16: =MIN('Estimates-on-the-use-of-water-('!H2:H214) -> 0 | C16: =QUARTILE('Estimates-on-the-use-of-water-('!H2:H214,1) -> 0 | D16: =MEDIAN('Estimates-on-the-use-of-water-('!H2:H214) -> 0 | E16: =QUARTILE('Estimates-on-the-use-of-water-('!H2:H214,3) -> 1.878302 | F16: =MAX('Estimates-on-the-use-of-water-('!H2:H214) -> 30.369793 | G16: =AVERAGE('Estimates-on-the-use-of-water-('!H2:H214) -> 1.9154886 | H16: =MODE('Estimates-on-the-use-of-water-('!H2:H214) -> 0 | I16: =F16-B16 -> 30.369793 | J16: =E16-C16 -> 1.878302 | K16: =STDEV('Estimates-on-the-use-of-water-('!H2:H214) -> 3.923974
B18: min | C18: q1 | D18: median q2 | E18: q3 | F18: max | G18: mean | H18: mode | I18: range | J18: (IQR)interquartile range | K18: standard deviation
A19: wat_bas_u | B19: =MIN('Estimates-on-the-use-of-water-('!M2:M214) -> 49.661665 | C19: =QUARTILE('Estimates-on-the-use-of-water-('!M2:M214,1) -> 92.562878 | D19: =MEDIAN('Estimates-on-the-use-of-water-('!M2:M214) -> 98.106628 | E19: =QUARTILE('Estimates-on-the-use-of-water-('!M2:M214,3) -> 99.949418 | F19: =MAX('Estimates-on-the-use-of-water-('!M2:M214) -> 100 | G19: =AVERAGE('Estimates-on-the-use-of-water-('!M2:M214) -> 94.68984 | H19: =MODE('Estimates-on-the-use-of-water-('!M2:M214) -> 100 | I19: =F19-B19 -> 50.338335 | J19: =E19-C19 -> 7.3865405 | K19: =STDEV('Estimates-on-the-use-of-water-('!M2:M214) -> 8.0388616
A20: wat_lim_u | B20: =MIN('Estimates-on-the-use-of-water-('!N2:N214) -> 0 | C20: =QUARTILE('Estimates-on-the-use-of-water-('!N2:N214,1) -> 0 | D20: =MEDIAN('Estimates-on-the-use-of-water-('!N2:N214) -> 0.5 | E20: =QUARTILE('Estimates-on-the-use-of-water-('!N2:N214,3) -> 3.9663472 | F20: =MAX('Estimates-on-the-use-of-water-('!N2:N214) -> 34.27978 | G20: =AVERAGE('Estimates-on-the-use-of-water-('!N2:N214) -> 3.2818387 | H20: =MODE('Estimates-on-the-use-of-water-('!N2:N214) -> 0 | I20: =F20-B20 -> 34.27978 | J20: =E20-C20 -> 3.9663472 | K20: =STDEV('Estimates-on-the-use-of-water-('!N2:N214) -> 5.635067
A21: wat_unimp_u | B21: =MIN('Estimates-on-the-use-of-water-('!O2:O214) -> 0 | C21: =QUARTILE('Estimates-on-the-use-of-water-('!O2:O214,1) -> 0 | D21: =MEDIAN('Estimates-on-the-use-of-water-('!O2:O214) -> 0.349874 | E21: =QUARTILE('Estimates-on-the-use-of-water-('!O2:O214,3) -> 2.0590013 | F21: =MAX('Estimates-on-the-use-of-water-('!O2:O214) -> 19.835807 | G21: =AVERAGE('Estimates-on-the-use-of-water-('!O2:O214) -> 1.7187852 | H21: =MODE('Estimates-on-the-use-of-water-('!O2:O214) -> 0 | I21: =F21-B21 -> 19.835807 | J21: =E21-C21 -> 2.0590013 | K21: =STDEV('Estimates-on-the-use-of-water-('!O2:O214) -> 3.2345703
A22: wat_sur_u | B22: =MIN('Estimates-on-the-use-of-water-('!P2:P214) -> 0 | C22: =QUARTILE('Estimates-on-the-use-of-water-('!P2:P214,1) -> 0 | D22: =MEDIAN('Estimates-on-the-use-of-water-('!P2:P214) -> 0 | E22: =QUARTILE('Estimates-on-the-use-of-water-('!P2:P214,3) -> 0.15970568 | F22: =MAX('Estimates-on-the-use-of-water-('!P2:P214) -> 6.3621605 | G22: =AVERAGE('Estimates-on-the-use-of-water-('!P2:P214) -> 0.31311484 | H22: =MODE('Estimates-on-the-use-of-water-('!P2:P214) -> 0 | I22: =F22-B22 -> 6.3621605 | J22: =E22-C22 -> 0.15970568 | K22: =STDEV('Estimates-on-the-use-of-water-('!P2:P214) -> 0.86963164
B24: min | C24: q1 | D24: median q2 | E24: q3 | F24: max | G24: mean | H24: mode | I24: range | J24: (IQR)interquartile range | K24: standard deviation
A25: wat_bas_r | B25: =MIN('Estimates-on-the-use-of-water-('!I2:I214) -> 21.982792 | C25: =QUARTILE('Estimates-on-the-use-of-water-('!I2:I214,1) -> 64.825421 | D25: =MEDIAN('Estimates-on-the-use-of-water-('!I2:I214) -> 90.731617 | E25: =QUARTILE('Estimates-on-the-use-of-water-('!I2:I214,3) -> 99.119242 | F25: =MAX('Estimates-on-the-use-of-water-('!I2:I214) -> 100 | G25: =AVERAGE('Estimates-on-the-use-of-water-('!I2:I214) -> 81.335918 | H25: =MODE('Estimates-on-the-use-of-water-('!I2:I214) -> 100 | I25: =F25-B25 -> 78.017208 | J25: =E25-C25 -> 34.293821 | K25: =STDEV('Estimates-on-the-use-of-water-('!I2:I214) -> 21.506637
A26: wat_lim_r | B26: =MIN('Estimates-on-the-use-of-water-('!J2:J214) -> 0 | C26: =QUARTILE('Estimates-on-the-use-of-water-('!J2:J214,1) -> 0 | D26: =MEDIAN('Estimates-on-the-use-of-water-('!J2:J214) -> 1.8123308 | E26: =QUARTILE('Estimates-on-the-use-of-water-('!J2:J214,3) -> 8.5531751 | F26: =MAX('Estimates-on-the-use-of-water-('!J2:J214) -> 42.164381 | G26: =AVERAGE('Estimates-on-the-use-of-water-('!J2:J214) -> 5.8365625 | H26: =MODE('Estimates-on-the-use-of-water-('!J2:J214) -> 0 | I26: =F26-B26 -> 42.164381 | J26: =E26-C26 -> 8.5531751 | K26: =STDEV('Estimates-on-the-use-of-water-('!J2:J214) -> 8.7047658
A27: wat_unimp_r | B27: =MIN('Estimates-on-the-use-of-water-('!K2:K214) -> 0 | C27: =QUARTILE('Estimates-on-the-use-of-water-('!K2:K214,1) -> 0.15841092 | D27: =MEDIAN('Estimates-on-the-use-of-water-('!K2:K214) -> 3.2297497 | E27: =QUARTILE('Estimates-on-the-use-of-water-('!K2:K214,3) -> 13.266339 | F27: =MAX('Estimates-on-the-use-of-water-('!K2:K214) -> 51.215982 | G27: =AVERAGE('Estimates-on-the-use-of-water-('!K2:K214) -> 8.7322615 | H27: =MODE('Estimates-on-the-use-of-water-('!K2:K214) -> 0 | I27: =F27-B27 -> 51.215982 | J27: =E27-C27 -> 13.107928 | K27: =STDEV('Estimates-on-the-use-of-water-('!K2:K214) -> 11.828494
A28: wat_sur_r | B28: =MIN('Estimates-on-the-use-of-water-('!L2:L214) -> 0 | C28: =QUARTILE('Estimates-on-the-use-of-water-('!L2:L214,1) -> 0 | D28: =MEDIAN('Estimates-on-the-use-of-water-('!L2:L214) -> 0.21968974 | E28: =QUARTILE('Estimates-on-the-use-of-water-('!L2:L214,3) -> 6.1574715 | F28: =MAX('Estimates-on-the-use-of-water-('!L2:L214) -> 40.518132 | G28: =AVERAGE('Estimates-on-the-use-of-water-('!L2:L214) -> 4.2240396 | H28: =MODE('Estimates-on-the-use-of-water-('!L2:L214) -> 0 | I28: =F28-B28 -> 40.518132 | J28: =E28-C28 -> 6.1574715 | K28: =STDEV('Estimates-on-the-use-of-water-('!L2:L214) -> 6.8479514
G145: NATIONAL PIVOT TABLE
G168: URBAN PIVOT TABLE
G195: RURAL PIVOT TABLE
